Workbook

Sheet 2026 Budget >>>

Sheet P&L
C2: 2026 Forecast
C3: Income Statement
C5: ($ in actual) | D5: 46023 | E5: =EOMONTH(D5,0)+1 -> 46054 | F5: =EOMONTH(E5,0)+1 -> 46082 | G5: =EOMONTH(F5,0)+1 -> 46113 | H5: =EOMONTH(G5,0)+1 -> 46143 | I5: =EOMONTH(H5,0)+1 -> 46174 | J5: =EOMONTH(I5,0)+1 -> 46204 | K5: =EOMONTH(J5,0)+1 -> 46235 | L5: =EOMONTH(K5,0)+1 -> 46266 | ... O5: =EOMONTH(N5,0)+1 -> 46357 | Q5: Q1 '26 | R5: Q2 '26 | S5: Q3 '26 | T5: Q4 '26 | V5: 2026E | W5: Steady State
C7: Revenue
C8: AI Monitoring | D8: ='Sales Forecast'!D37+'Sales Forecast'!D43 -> 0 | E8: ='Sales Forecast'!E37+'Sales Forecast'!E43 -> 0 | F8: ='Sales Forecast'!F37+'Sales Forecast'!F43 -> 0 | G8: ='Sales Forecast'!G37+'Sales Forecast'!G43 -> 7500 | H8: ='Sales Forecast'!H37+'Sales Forecast'!H43 -> 15000 | I8: ='Sales Forecast'!I37+'Sales Forecast'!I43 -> 22500 | J8: ='Sales Forecast'!J37+'Sales Forecast'!J43 -> 45000 | K8: ='Sales Forecast'!K37+'Sales Forecast'!K43 -> 82500 | ... O8: ='Sales Forecast'!O37+'Sales Forecast'!O43 -> 375000 | Q8: =SUM(D8:F8) -> 0 | R8: =SUM(G8:I8) -> 45000 | S8: =SUM(J8:L8) -> 255000 | T8: =SUM(M8:O8) -> 862500 | V8: =SUM(Q8:T8) -> 1162500 | W8: =SUM('Sales Forecast'!D7:O7)*'Solution Offering'!J5*'Product & Pricing List'!P5*12+SUM('Sales Forecast'!D8:O8)*'Solution Offering'!J5*'Product & Pricing List'!P6*12 -> 8280000
C9: Integration Fee | D9: ='Sales Forecast'!D38+'Sales Forecast'!D44 -> 0 | E9: ='Sales Forecast'!E38+'Sales Forecast'!E44 -> 0 | F9: ='Sales Forecast'!F38+'Sales Forecast'!F44 -> 0 | G9: ='Sales Forecast'!G38+'Sales Forecast'!G44 -> 0 | H9: ='Sales Forecast'!H38+'Sales Forecast'!H44 -> 0 | I9: ='Sales Forecast'!I38+'Sales Forecast'!I44 -> 0 | J9: ='Sales Forecast'!J38+'Sales Forecast'!J44 -> 0 | K9: ='Sales Forecast'!K38+'Sales Forecast'!K44 -> 0 | ... O9: ='Sales Forecast'!O38+'Sales Forecast'!O44 -> 0 | Q9: =SUM(D9:F9) -> 0 | R9: =SUM(G9:I9) -> 0 | S9: =SUM(J9:L9) -> 0 | T9: =SUM(M9:O9) -> 0 | V9: =SUM(Q9:T9) -> 0 | W9: 0
C10: Professional Services - Implementation | D10: ='Sales Forecast'!D39+'Sales Forecast'!D45 -> 0 | E10: ='Sales Forecast'!E39+'Sales Forecast'!E45 -> 765 | F10: ='Sales Forecast'!F39+'Sales Forecast'!F45 -> 765 | G10: ='Sales Forecast'!G39+'Sales Forecast'!G45 -> 2295 | H10: ='Sales Forecast'!H39+'Sales Forecast'!H45 -> 3825 | I10: ='Sales Forecast'!I39+'Sales Forecast'!I45 -> 4590 | J10: ='Sales Forecast'!J39+'Sales Forecast'!J45 -> 7650 | K10: ='Sales Forecast'!K39+'Sales Forecast'!K45 -> 8415 | ... O10: ='Sales Forecast'!O39+'Sales Forecast'!O45 -> 11475 | Q10: =SUM(D10:F10) -> 1530 | R10: =SUM(G10:I10) -> 10710 | S10: =SUM(J10:L10) -> 25245 | T10: =SUM(M10:O10) -> 32130 | V10: =SUM(Q10:T10) -> 69615 | W10: 0
C11: Professional Services - Monthly | D11: ='Sales Forecast'!D40+'Sales Forecast'!D46 -> 0 | E11: ='Sales Forecast'!E40+'Sales Forecast'!E46 -> 0 | F11: ='Sales Forecast'!F40+'Sales Forecast'!F46 -> 0 | G11: ='Sales Forecast'!G40+'Sales Forecast'!G46 -> 765 | H11: ='Sales Forecast'!H40+'Sales Forecast'!H46 -> 1530 | I11: ='Sales Forecast'!I40+'Sales Forecast'!I46 -> 2295 | J11: ='Sales Forecast'!J40+'Sales Forecast'!J46 -> 4590 | K11: ='Sales Forecast'!K40+'Sales Forecast'!K46 -> 8415 | ... O11: ='Sales Forecast'!O40+'Sales Forecast'!O46 -> 38250 | Q11: =SUM(D11:F11) -> 0 | R11: =SUM(G11:I11) -> 4590 | S11: =SUM(J11:L11) -> 26010 | T11: =SUM(M11:O11) -> 87975 | V11: =SUM(Q11:T11) -> 118575 | W11: =SUM('Sales Forecast'!D7:O7)*'Solution Offering'!J8*'Product & Pricing List'!P8*12+SUM('Sales Forecast'!D8:O8)*'Solution Offering'!J8*'Product & Pricing List'!P8*12 -> 844560
C12: Total Revenue | D12: =SUM(D8:D11) -> 0 | E12: =SUM(E8:E11) -> 765 | F12: =SUM(F8:F11) -> 765 | G12: =SUM(G8:G11) -> 10560 | H12: =SUM(H8:H11) -> 20355 | I12: =SUM(I8:I11) -> 29385 | J12: =SUM(J8:J11) -> 57240 | K12: =SUM(K8:K11) -> 99330 | ... O12: =SUM(O8:O11) -> 424725 | Q12: =SUM(Q8:Q11) -> 1530 | R12: =SUM(R8:R11) -> 60300 | S12: =SUM(S8:S11) -> 306255 | T12: =SUM(T8:T11) -> 982605 | V12: =SUM(V8:V11) -> 1350690 | W12: =SUM(W8:W11) -> 9124560
C13: ARR | D13: =SUM(D8:D8)*12 -> 0 | E13: =SUM(E8:E8)*12 -> 0 | F13: =SUM(F8:F8)*12 -> 0 | G13: =SUM(G8:G8)*12 -> 90000 | H13: =SUM(H8:H8)*12 -> 180000 | I13: =SUM(I8:I8)*12 -> 270000 | J13: =SUM(J8:J8)*12 -> 540000 | K13: =SUM(K8:K8)*12 -> 990000 | ... O13: =SUM(O8:O8)*12 -> 4500000 | Q13: =F13 -> 0 | R13: =I13 -> 270000 | S13: =L13 -> 1530000 | T13: =O13 -> 4500000 | V13: =T13 -> 4500000 | W13: =SUM(W8:W8) -> 8280000
C14: Software % of Total Revenue | D14: =IFERROR(SUM(D8:D8)/D$12,"nm") -> nm | E14: =IFERROR(SUM(E8:E8)/E$12,"nm") -> 0 | F14: =IFERROR(SUM(F8:F8)/F$12,"nm") -> 0 | G14: =IFERROR(SUM(G8:G8)/G$12,"nm") -> 0.71022727 | H14: =IFERROR(SUM(H8:H8)/H$12,"nm") -> 0.73691968 | I14: =IFERROR(SUM(I8:I8)/I$12,"nm") -> 0.76569678 | J14: =IFERROR(SUM(J8:J8)/J$12,"nm") -> 0.78616352 | K14: =IFERROR(SUM(K8:K8)/K$12,"nm") -> 0.83056478 | ... O14: =IFERROR(SUM(O8:O8)/O$12,"nm") -> 0.88292425 | Q14: =IFERROR(SUM(Q8:Q8)/Q$12,"nm") -> 0 | R14: =IFERROR(SUM(R8:R8)/R$12,"nm") -> 0.74626866 | S14: =IFERROR(SUM(S8:S8)/S$12,"nm") -> 0.83263947 | T14: =IFERROR(SUM(T8:T8)/T$12,"nm") -> 0.87776879 | V14: =IFERROR(SUM(V8:V8)/V$12,"nm") -> 0.86067121 | W14: =IFERROR(SUM(W8:W8)/W$12,"nm") -> 0.90744102
C15: Services % of Total Revenue | D15: =IFERROR(SUM(D9:D11)/D$12,"nm") -> nm | E15: =IFERROR(SUM(E9:E11)/E$12,"nm") -> 1 | F15: =IFERROR(SUM(F9:F11)/F$12,"nm") -> 1 | G15: =IFERROR(SUM(G9:G11)/G$12,"nm") -> 0.28977273 | H15: =IFERROR(SUM(H9:H11)/H$12,"nm") -> 0.26308032 | I15: =IFERROR(SUM(I9:I11)/I$12,"nm") -> 0.23430322 | J15: =IFERROR(SUM(J9:J11)/J$12,"nm") -> 0.21383648 | K15: =IFERROR(SUM(K9:K11)/K$12,"nm") -> 0.16943522 | ... O15: =IFERROR(SUM(O9:O11)/O$12,"nm") -> 0.11707575 | Q15: =IFERROR(SUM(Q9:Q11)/Q$12,"nm") -> 1 | R15: =IFERROR(SUM(R9:R11)/R$12,"nm") -> 0.25373134 | S15: =IFERROR(SUM(S9:S11)/S$12,"nm") -> 0.16736053 | T15: =IFERROR(SUM(T9:T11)/T$12,"nm") -> 0.12223121 | V15: =IFERROR(SUM(V9:V11)/V$12,"nm") -> 0.13932879 | W15: =IFERROR(SUM(W9:W11)/W$12,"nm") -> 0.092558984
C17: Cost of Goods Sold
C18: AI Monitoring | D18: =Labor!F40+Labor!F46+'Third Party Software'!E24+'Third Party Software'!E30+'Hosting & Internet Fees'!F22+'Hosting & Internet Fees'!F30+Other!E14+Other!E20 -> 350 | E18: =Labor!G40+Labor!G46+'Third Party Software'!F24+'Third Party Software'!F30+'Hosting & Internet Fees'!G22+'Hosting & Internet Fees'!G30+Other!F14+Other!F20 -> 367.5 | F18: =Labor!H40+Labor!H46+'Third Party Software'!G24+'Third Party Software'!G30+'Hosting & Internet Fees'!H22+'Hosting & Internet Fees'!H30+Other!G14+Other!G20 -> 385.875 | G18: =Labor!I40+Labor!I46+'Third Party Software'!H24+'Third Party Software'!H30+'Hosting & Internet Fees'!I22+'Hosting & Internet Fees'!I30+Other!H14+Other!H20 -> 31395.679 | H18: =Labor!J40+Labor!J46+'Third Party Software'!I24+'Third Party Software'!I30+'Hosting & Internet Fees'!J22+'Hosting & Internet Fees'!J30+Other!I14+Other!I20 -> 62458.541 | I18: =Labor!K40+Labor!K46+'Third Party Software'!J24+'Third Party Software'!J30+'Hosting & Internet Fees'!K22+'Hosting & Internet Fees'!K30+Other!J14+Other!J20 -> 93549.138 | J18: =Labor!L40+Labor!L46+'Third Party Software'!K24+'Third Party Software'!K30+'Hosting & Internet Fees'!L22+'Hosting & Internet Fees'!L30+Other!K14+Other!K20 -> 186751.59 | K18: =Labor!M40+Labor!M46+'Third Party Software'!L24+'Third Party Software'!L30+'Hosting & Internet Fees'!M22+'Hosting & Internet Fees'!M30+Other!L14+Other!L20 -> 343431.23 | ... O18: =Labor!Q40+Labor!Q46+'Third Party Software'!P24+'Third Party Software'!P30+'Hosting & Internet Fees'!Q22+'Hosting & Internet Fees'!Q30+Other!P14+Other!P20 -> 1563338.3 | Q18: =SUM(D18:F18) -> 1103.375 | R18: =SUM(G18:I18) -> 187403.36 | S18: =SUM(J18:L18) -> 1060261.6 | T18: =SUM(M18:O18) -> 3591596.5 | V18: =SUM(Q18:T18) -> 4840364.9 | W18: =O18*12 -> 18760059
C19: Integration Fee | D19: =Labor!F41+Labor!F47+'Third Party Software'!E25+'Third Party Software'!E31+'Hosting & Internet Fees'!F23+'Hosting & Internet Fees'!F31+Other!E15+Other!E21 -> 0 | E19: =Labor!G41+Labor!G47+'Third Party Software'!F25+'Third Party Software'!F31+'Hosting & Internet Fees'!G23+'Hosting & Internet Fees'!G31+Other!F15+Other!F21 -> 0 | F19: =Labor!H41+Labor!H47+'Third Party Software'!G25+'Third Party Software'!G31+'Hosting & Internet Fees'!H23+'Hosting & Internet Fees'!H31+Other!G15+Other!G21 -> 0 | G19: =Labor!I41+Labor!I47+'Third Party Software'!H25+'Third Party Software'!H31+'Hosting & Internet Fees'!I23+'Hosting & Internet Fees'!I31+Other!H15+Other!H21 -> 0 | H19: =Labor!J41+Labor!J47+'Third Party Software'!I25+'Third Party Software'!I31+'Hosting & Internet Fees'!J23+'Hosting & Internet Fees'!J31+Other!I15+Other!I21 -> 0 | I19: =Labor!K41+Labor!K47+'Third Party Software'!J25+'Third Party Software'!J31+'Hosting & Internet Fees'!K23+'Hosting & Internet Fees'!K31+Other!J15+Other!J21 -> 0 | J19: =Labor!L41+Labor!L47+'Third Party Software'!K25+'Third Party Software'!K31+'Hosting & Internet Fees'!L23+'Hosting & Internet Fees'!L31+Other!K15+Other!K21 -> 0 | K19: =Labor!M41+Labor!M47+'Third Party Software'!L25+'Third Party Software'!L31+'Hosting & Internet Fees'!M23+'Hosting & Internet Fees'!M31+Other!L15+Other!L21 -> 0 | ... O19: =Labor!Q41+Labor!Q47+'Third Party Software'!P25+'Third Party Software'!P31+'Hosting & Internet Fees'!Q23+'Hosting & Internet Fees'!Q31+Other!P15+Other!P21 -> 0 | Q19: =SUM(D19:F19) -> 0 | R19: =SUM(G19:I19) -> 0 | S19: =SUM(J19:L19) -> 0 | T19: =SUM(M19:O19) -> 0 | V19: =SUM(Q19:T19) -> 0 | W19: 0
C20: Professional Services - Implementation | D20: =Labor!F42+Labor!F48+'Third Party Software'!E26+'Third Party Software'!E32+'Hosting & Internet Fees'!F24+'Hosting & Internet Fees'!F32+Other!E16+Other!E22 -> 0 | E20: =Labor!G42+Labor!G48+'Third Party Software'!F26+'Third Party Software'!F32+'Hosting & Internet Fees'!G24+'Hosting & Internet Fees'!G32+Other!F16+Other!F22 -> 462.8726 | F20: =Labor!H42+Labor!H48+'Third Party Software'!G26+'Third Party Software'!G32+'Hosting & Internet Fees'!H24+'Hosting & Internet Fees'!H32+Other!G16+Other!G22 -> 462.8726 | G20: =Labor!I42+Labor!I48+'Third Party Software'!H26+'Third Party Software'!H32+'Hosting & Internet Fees'!I24+'Hosting & Internet Fees'!I32+Other!H16+Other!H22 -> 1388.6178 | H20: =Labor!J42+Labor!J48+'Third Party Software'!I26+'Third Party Software'!I32+'Hosting & Internet Fees'!J24+'Hosting & Internet Fees'!J32+Other!I16+Other!I22 -> 2314.363 | I20: =Labor!K42+Labor!K48+'Third Party Software'!J26+'Third Party Software'!J32+'Hosting & Internet Fees'!K24+'Hosting & Internet Fees'!K32+Other!J16+Other!J22 -> 2777.2356 | J20: =Labor!L42+Labor!L48+'Third Party Software'!K26+'Third Party Software'!K32+'Hosting & Internet Fees'!L24+'Hosting & Internet Fees'!L32+Other!K16+Other!K22 -> 4628.726 | K20: =Labor!M42+Labor!M48+'Third Party Software'!L26+'Third Party Software'!L32+'Hosting & Internet Fees'!M24+'Hosting & Internet Fees'!M32+Other!L16+Other!L22 -> 5091.5986 | ... O20: =Labor!Q42+Labor!Q48+'Third Party Software'!P26+'Third Party Software'!P32+'Hosting & Internet Fees'!Q24+'Hosting & Internet Fees'!Q32+Other!P16+Other!P22 -> 6943.0889 | Q20: =SUM(D20:F20) -> 925.74519 | R20: =SUM(G20:I20) -> 6480.2163 | S20: =SUM(J20:L20) -> 15274.796 | T20: =SUM(M20:O20) -> 19440.649 | V20: =SUM(Q20:T20) -> 42121.406 | W20: 0
C21: Professional Services - Monthly | D21: =Labor!F43+Labor!F49+'Third Party Software'!E27+'Third Party Software'!E33+'Hosting & Internet Fees'!F25+'Hosting & Internet Fees'!F33+Other!E17+Other!E23 -> 0 | E21: =Labor!G43+Labor!G49+'Third Party Software'!F27+'Third Party Software'!F33+'Hosting & Internet Fees'!G25+'Hosting & Internet Fees'!G33+Other!F17+Other!F23 -> 0 | F21: =Labor!H43+Labor!H49+'Third Party Software'!G27+'Third Party Software'!G33+'Hosting & Internet Fees'!H25+'Hosting & Internet Fees'!H33+Other!G17+Other!G23 -> 0 | G21: =Labor!I43+Labor!I49+'Third Party Software'!H27+'Third Party Software'!H33+'Hosting & Internet Fees'!I25+'Hosting & Internet Fees'!I33+Other!H17+Other!H23 -> 462.8726 | H21: =Labor!J43+Labor!J49+'Third Party Software'!I27+'Third Party Software'!I33+'Hosting & Internet Fees'!J25+'Hosting & Internet Fees'!J33+Other!I17+Other!I23 -> 925.74519 | I21: =Labor!K43+Labor!K49+'Third Party Software'!J27+'Third Party Software'!J33+'Hosting & Internet Fees'!K25+'Hosting & Internet Fees'!K33+Other!J17+Other!J23 -> 1388.6178 | J21: =Labor!L43+Labor!L49+'Third Party Software'!K27+'Third Party Software'!K33+'Hosting & Internet Fees'!L25+'Hosting & Internet Fees'!L33+Other!K17+Other!K23 -> 2777.2356 | K21: =Labor!M43+Labor!M49+'Third Party Software'!L27+'Third Party Software'!L33+'Hosting & Internet Fees'!M25+'Hosting & Internet Fees'!M33+Other!L17+Other!L23 -> 5091.5986 | ... O21: =Labor!Q43+Labor!Q49+'Third Party Software'!P27+'Third Party Software'!P33+'Hosting & Internet Fees'!Q25+'Hosting & Internet Fees'!Q33+Other!P17+Other!P23 -> 23143.63 | Q21: =SUM(D21:F21) -> 0 | R21: =SUM(G21:I21) -> 2777.2356 | S21: =SUM(J21:L21) -> 15737.668 | T21: =SUM(M21:O21) -> 53230.349 | V21: =SUM(Q21:T21) -> 71745.252 | W21: =SUM('Sales Forecast'!D7:O8)*'Solution Offering'!J8*Labor!X20*12 -> 511011.35
C22: Total Cost of Goods Sold | D22: =SUM(D18:D21) -> 350 | E22: =SUM(E18:E21) -> 830.3726 | F22: =SUM(F18:F21) -> 848.7476 | G22: =SUM(G18:G21) -> 33247.17 | H22: =SUM(H18:H21) -> 65698.65 | I22: =SUM(I18:I21) -> 97714.992 | J22: =SUM(J18:J21) -> 194157.55 | K22: =SUM(K18:K21) -> 353614.43 | ... O22: =SUM(O18:O21) -> 1593425 | Q22: =SUM(Q18:Q21) -> 2029.1202 | R22: =SUM(R18:R21) -> 196660.81 | S22: =SUM(S18:S21) -> 1091274.1 | T22: =SUM(T18:T21) -> 3664267.5 | V22: =SUM(V18:V21) -> 4954231.6 | W22: =SUM(W18:W21) -> 19271070
C23: % of Total Revenue | D23: =IFERROR(D22/D$12,"nm") -> nm | E23: =IFERROR(E22/E$12,"nm") -> 1.0854544 | F23: =IFERROR(F22/F$12,"nm") -> 1.109474 | G23: =IFERROR(G22/G$12,"nm") -> 3.1484062 | H23: =IFERROR(H22/H$12,"nm") -> 3.2276418 | I23: =IFERROR(I22/I$12,"nm") -> 3.3253358 | J23: =IFERROR(J22/J$12,"nm") -> 3.3919908 | K23: =IFERROR(K22/K$12,"nm") -> 3.5599963 | ... O23: =IFERROR(O22/O$12,"nm") -> 3.7516628 | Q23: =IFERROR(Q22/Q$12,"nm") -> 1.3262223 | R23: =IFERROR(R22/R$12,"nm") -> 3.2613733 | S23: =IFERROR(S22/S$12,"nm") -> 3.5632859 | T23: =IFERROR(T22/T$12,"nm") -> 3.7291358 | V23: =IFERROR(V22/V$12,"nm") -> 3.6679264 | W23: =IFERROR(W22/W$12,"nm") -> 2.112
C25: Gross Profit | D25: =D12-D22 -> -350 | E25: =E12-E22 -> -65.372596 | F25: =F12-F22 -> -83.747596 | G25: =G12-G22 -> -22687.17 | H25: =H12-H22 -> -45343.65 | I25: =I12-I22 -> -68329.992 | J25: =J12-J22 -> -136917.55 | K25: =K12-K22 -> -254284.43 | ... O25: =O12-O22 -> -1168700 | Q25: =Q12-Q22 -> -499.12019 | R25: =R12-R22 -> -136360.81 | S25: =S12-S22 -> -785019.11 | T25: =T12-T22 -> -2681662.5 | V25: =V12-V22 -> -3603541.6 | W25: =W12-W22 -> -10146510
C26: AFFIRM Base Subscription % Margin | D26: =IFERROR((#REF!-#REF!)/#REF!,"nm") -> nm | E26: =IFERROR((#REF!-#REF!)/#REF!,"nm") -> nm | F26: =IFERROR((#REF!-#REF!)/#REF!,"nm") -> nm | G26: =IFERROR((#REF!-#REF!)/#REF!,"nm") -> nm | H26: =IFERROR((#REF!-#REF!)/#REF!,"nm") -> nm | I26: =IFERROR((#REF!-#REF!)/#REF!,"nm") -> nm | J26: =IFERROR((#REF!-#REF!)/#REF!,"nm") -> nm | K26: =IFERROR((#REF!-#REF!)/#REF!,"nm") -> nm | ... O26: =IFERROR((#REF!-#REF!)/#REF!,"nm") -> nm | Q26: =IFERROR((#REF!-#REF!)/#REF!,"nm") -> nm | R26: =IFERROR((#REF!-#REF!)/#REF!,"nm") -> nm | S26: =IFERROR((#REF!-#REF!)/#REF!,"nm") -> nm | T26: =IFERROR((#REF!-#REF!)/#REF!,"nm") -> nm | V26: =IFERROR((#REF!-#REF!)/#REF!,"nm") -> nm | W26: =IFERROR((#REF!-#REF!)/#REF!,"nm") -> nm
C27: Framework Pack % Margin | D27: =IFERROR((#REF!-#REF!)/#REF!,"nm") -> nm | E27: =IFERROR((#REF!-#REF!)/#REF!,"nm") -> nm | F27: =IFERROR((#REF!-#REF!)/#REF!,"nm") -> nm | G27: =IFERROR((#REF!-#REF!)/#REF!,"nm") -> nm | H27: =IFERROR((#REF!-#REF!)/#REF!,"nm") -> nm | I27: =IFERROR((#REF!-#REF!)/#REF!,"nm") -> nm | J27: =IFERROR((#REF!-#REF!)/#REF!,"nm") -> nm | K27: =IFERROR((#REF!-#REF!)/#REF!,"nm") -> nm | ... O27: =IFERROR((#REF!-#REF!)/#REF!,"nm") -> nm | Q27: =IFERROR((#REF!-#REF!)/#REF!,"nm") -> nm | R27: =IFERROR((#REF!-#REF!)/#REF!,"nm") -> nm | S27: =IFERROR((#REF!-#REF!)/#REF!,"nm") -> nm | T27: =IFERROR((#REF!-#REF!)/#REF!,"nm") -> nm | V27: =IFERROR((#REF!-#REF!)/#REF!,"nm") -> nm | W27: =IFERROR((#REF!-#REF!)/#REF!,"nm") -> nm
C28: AI Monitoring % Margin | D28: =IFERROR((D8-D18)/D8,"nm") -> nm | E28: =IFERROR((E8-E18)/E8,"nm") -> nm | F28: =IFERROR((F8-F18)/F8,"nm") -> nm | G28: =IFERROR((G8-G18)/G8,"nm") -> -3.1860906 | H28: =IFERROR((H8-H18)/H8,"nm") -> -3.1639028 | I28: =IFERROR((I8-I18)/I8,"nm") -> -3.1577395 | J28: =IFERROR((J8-J18)/J8,"nm") -> -3.1500354 | K28: =IFERROR((K8-K18)/K8,"nm") -> -3.1628028 | ... O28: =IFERROR((O8-O18)/O8,"nm") -> -3.168902 | Q28: =IFERROR((Q8-Q18)/Q8,"nm") -> nm | R28: =IFERROR((R8-R18)/R8,"nm") -> -3.1645191 | S28: =IFERROR((S8-S18)/S8,"nm") -> -3.1578888 | T28: =IFERROR((T8-T18)/T8,"nm") -> -3.1641699 | V28: =IFERROR((V8-V18)/V8,"nm") -> -3.1637548 | W28: =IFERROR((W8-W18)/W8,"nm") -> -1.2657076
C29: Usage Fee % Margin | D29: =IFERROR((#REF!-#REF!)/#REF!,"nm") -> nm | E29: =IFERROR((#REF!-#REF!)/#REF!,"nm") -> nm | F29: =IFERROR((#REF!-#REF!)/#REF!,"nm") -> nm | G29: =IFERROR((#REF!-#REF!)/#REF!,"nm") -> nm | H29: =IFERROR((#REF!-#REF!)/#REF!,"nm") -> nm | I29: =IFERROR((#REF!-#REF!)/#REF!,"nm") -> nm | J29: =IFERROR((#REF!-#REF!)/#REF!,"nm") -> nm | K29: =IFERROR((#REF!-#REF!)/#REF!,"nm") -> nm | ... O29: =IFERROR((#REF!-#REF!)/#REF!,"nm") -> nm | Q29: =IFERROR((#REF!-#REF!)/#REF!,"nm") -> nm | R29: =IFERROR((#REF!-#REF!)/#REF!,"nm") -> nm | S29: =IFERROR((#REF!-#REF!)/#REF!,"nm") -> nm | T29: =IFERROR((#REF!-#REF!)/#REF!,"nm") -> nm | V29: =IFERROR((#REF!-#REF!)/#REF!,"nm") -> nm | W29: =IFERROR((#REF!-#REF!)/#REF!,"nm") -> nm
C30: Integration Fee % Margin | D30: =IFERROR((D9-D19)/D9,"nm") -> nm | E30: =IFERROR((E9-E19)/E9,"nm") -> nm | F30: =IFERROR((F9-F19)/F9,"nm") -> nm | G30: =IFERROR((G9-G19)/G9,"nm") -> nm | H30: =IFERROR((H9-H19)/H9,"nm") -> nm | I30: =IFERROR((I9-I19)/I9,"nm") -> nm | J30: =IFERROR((J9-J19)/J9,"nm") -> nm | K30: =IFERROR((K9-K19)/K9,"nm") -> nm | ... O30: =IFERROR((O9-O19)/O9,"nm") -> nm | Q30: =IFERROR((Q9-Q19)/Q9,"nm") -> nm | R30: =IFERROR((R9-R19)/R9,"nm") -> nm | S30: =IFERROR((S9-S19)/S9,"nm") -> nm | T30: =IFERROR((T9-T19)/T9,"nm") -> nm | V30: =IFERROR((V9-V19)/V9,"nm") -> nm | W30: =IFERROR((W9-W19)/W9,"nm") -> nm
C31: Professional Services - Implementation % Margin | D31: =IFERROR((D10-D20)/D10,"nm") -> nm | E31: =IFERROR((E10-E20)/E10,"nm") -> 0.39493778 | F31: =IFERROR((F10-F20)/F10,"nm") -> 0.39493778 | G31: =IFERROR((G10-G20)/G10,"nm") -> 0.39493778 | H31: =IFERROR((H10-H20)/H10,"nm") -> 0.39493778 | I31: =IFERROR((I10-I20)/I10,"nm") -> 0.39493778 | J31: =IFERROR((J10-J20)/J10,"nm") -> 0.39493778 | K31: =IFERROR((K10-K20)/K10,"nm") -> 0.39493778 | ... O31: =IFERROR((O10-O20)/O10,"nm") -> 0.39493778 | Q31: =IFERROR((Q10-Q20)/Q10,"nm") -> 0.39493778 | R31: =IFERROR((R10-R20)/R10,"nm") -> 0.39493778 | S31: =IFERROR((S10-S20)/S10,"nm") -> 0.39493778 | T31: =IFERROR((T10-T20)/T10,"nm") -> 0.39493778 | V31: =IFERROR((V10-V20)/V10,"nm") -> 0.39493778 | W31: =IFERROR((W10-W20)/W10,"nm") -> nm
C32: Professional Services - Monthly % Margin | D32: =IFERROR((D11-D21)/D11,"nm") -> nm | E32: =IFERROR((E11-E21)/E11,"nm") -> nm | F32: =IFERROR((F11-F21)/F11,"nm") -> nm | G32: =IFERROR((G11-G21)/G11,"nm") -> 0.39493778 | H32: =IFERROR((H11-H21)/H11,"nm") -> 0.39493778 | I32: =IFERROR((I11-I21)/I11,"nm") -> 0.39493778 | J32: =IFERROR((J11-J21)/J11,"nm") -> 0.39493778 | K32: =IFERROR((K11-K21)/K11,"nm") -> 0.39493778 | ... O32: =IFERROR((O11-O21)/O11,"nm") -> 0.39493778 | Q32: =IFERROR((Q11-Q21)/Q11,"nm") -> nm | R32: =IFERROR((R11-R21)/R11,"nm") -> 0.39493778 | S32: =IFERROR((S11-S21)/S11,"nm") -> 0.39493778 | T32: =IFERROR((T11-T21)/T11,"nm") -> 0.39493778 | V32: =IFERROR((V11-V21)/V11,"nm") -> 0.39493778 | W32: =IFERROR((W11-W21)/W11,"nm") -> 0.39493778
C33: Total % Margin | D33: =IFERROR(D25/D$12,"nm") -> nm | E33: =IFERROR(E25/E$12,"nm") -> -0.085454374 | F33: =IFERROR(F25/F$12,"nm") -> -0.10947398 | G33: =IFERROR(G25/G$12,"nm") -> -2.1484062 | H33: =IFERROR(H25/H$12,"nm") -> -2.2276418 | I33: =IFERROR(I25/I$12,"nm") -> -2.3253358 | J33: =IFERROR(J25/J$12,"nm") -> -2.3919908 | K33: =IFERROR(K25/K$12,"nm") -> -2.5599963 | ... O33: =IFERROR(O25/O$12,"nm") -> -2.7516628 | Q33: =IFERROR(Q25/Q$12,"nm") -> -0.32622235 | R33: =IFERROR(R25/R$12,"nm") -> -2.2613733 | S33: =IFERROR(S25/S$12,"nm") -> -2.5632859 | T33: =IFERROR(T25/T$12,"nm") -> -2.7291358 | V33: =IFERROR(V25/V$12,"nm") -> -2.6679264 | W33: =IFERROR(W25/W$12,"nm") -> -1.112
C35: Operating Expenses
C36: Salaries, Wages, & Benefits | D36: ='Salaries, Wages, & Benefits'!F52 -> 106535.84 | E36: ='Salaries, Wages, & Benefits'!G52 -> 104570.28 | F36: ='Salaries, Wages, & Benefits'!H52 -> 101192.7 | G36: ='Salaries, Wages, & Benefits'!I52 -> 98889.929 | H36: ='Salaries, Wages, & Benefits'!J52 -> 93087.17 | I36: ='Salaries, Wages, & Benefits'!K52 -> 86743.45 | J36: ='Salaries, Wages, & Benefits'!L52 -> 69457.96 | K36: ='Salaries, Wages, & Benefits'!M52 -> 41193.778 | ... O36: ='Salaries, Wages, & Benefits'!Q52 -> -178950.33 | Q36: =SUM(D36:F36) -> 312298.83 | R36: =SUM(G36:I36) -> 278720.55 | S36: =SUM(J36:L36) -> 117945.16 | T36: =SUM(M36:O36) -> -339334.89 | V36: =SUM(Q36:T36) -> 369629.64 | W36: =V36 -> 369629.64
C37: Sales Commissions | D37: ='Sales Forecast'!D63 -> 0 | E37: ='Sales Forecast'!E63 -> 153 | F37: ='Sales Forecast'!F63 -> 153 | G37: ='Sales Forecast'!G63 -> 2112 | H37: ='Sales Forecast'!H63 -> 4071 | I37: ='Sales Forecast'!I63 -> 5877 | J37: ='Sales Forecast'!J63 -> 11448 | K37: ='Sales Forecast'!K63 -> 19866 | ... O37: ='Sales Forecast'!O63 -> 84945 | Q37: =SUM(D37:F37) -> 306 | R37: =SUM(G37:I37) -> 12060 | S37: =SUM(J37:L37) -> 61251 | T37: =SUM(M37:O37) -> 196521 | V37: =SUM(Q37:T37) -> 270138 | W37: 0
C38: Contract Labor | D38: ='Contract Labor'!I25 -> 104440 | E38: ='Contract Labor'!J25 -> 104440 | F38: ='Contract Labor'!K25 -> 104440 | G38: ='Contract Labor'!L25 -> 104440 | H38: ='Contract Labor'!M25 -> 104440 | I38: ='Contract Labor'!N25 -> 104440 | J38: ='Contract Labor'!O25 -> 104440 | K38: ='Contract Labor'!P25 -> 104440 | ... O38: ='Contract Labor'!T25 -> 104440 | Q38: =SUM(D38:F38) -> 313320 | R38: =SUM(G38:I38) -> 313320 | S38: =SUM(J38:L38) -> 313320 | T38: =SUM(M38:O38) -> 313320 | V38: =SUM(Q38:T38) -> 1253280 | W38: =V38 -> 1253280
C39: Professional Fees | D39: ='Professional Fees'!E10 -> 4500 | E39: ='Professional Fees'!F10 -> 9500 | F39: ='Professional Fees'!G10 -> 9500 | G39: ='Professional Fees'!H10 -> 9500 | H39: ='Professional Fees'!I10 -> 4500 | I39: ='Professional Fees'!J10 -> 7000 | J39: ='Professional Fees'!K10 -> 7000 | K39: ='Professional Fees'!L10 -> 7000 | ... O39: ='Professional Fees'!P10 -> 7000 | Q39: =SUM(D39:F39) -> 23500 | R39: =SUM(G39:I39) -> 21000 | S39: =SUM(J39:L39) -> 21000 | T39: =SUM(M39:O39) -> 21000 | V39: =SUM(Q39:T39) -> 86500 | W39: =V39 -> 86500
C40: Office Expenses | D40: ='Office Expenses'!E31 -> 4401 | E40: ='Office Expenses'!F31 -> 5149.11 | F40: ='Office Expenses'!G31 -> 3376 | G40: ='Office Expenses'!H31 -> 5836 | H40: ='Office Expenses'!I31 -> 7418 | I40: ='Office Expenses'!J31 -> 4216 | J40: ='Office Expenses'!K31 -> 3376 | K40: ='Office Expenses'!L31 -> 3376 | ... O40: ='Office Expenses'!P31 -> 3376 | Q40: =SUM(D40:F40) -> 12926.11 | R40: =SUM(G40:I40) -> 17470 | S40: =SUM(J40:L40) -> 13128 | T40: =SUM(M40:O40) -> 10128 | V40: =SUM(Q40:T40) -> 53652.11 | W40: =V40 -> 53652.11
C41: Advertising & Marketing | D41: ='Advertising & Marketing'!E12 -> 1279 | E41: ='Advertising & Marketing'!F12 -> 4279 | F41: ='Advertising & Marketing'!G12 -> 4279 | G41: ='Advertising & Marketing'!H12 -> 4279 | H41: ='Advertising & Marketing'!I12 -> 4279 | I41: ='Advertising & Marketing'!J12 -> 4279 | J41: ='Advertising & Marketing'!K12 -> 4279 | K41: ='Advertising & Marketing'!L12 -> 4279 | ... O41: ='Advertising & Marketing'!P12 -> 4279 | Q41: =SUM(D41:F41) -> 9837 | R41: =SUM(G41:I41) -> 12837 | S41: =SUM(J41:L41) -> 12837 | T41: =SUM(M41:O41) -> 12837 | V41: =SUM(Q41:T41) -> 48348 | W41: =V41 -> 48348
C42: Employee Travel | D42: ='Employee Travel'!D14 -> 12400 | E42: ='Employee Travel'!E14 -> 12250 | F42: ='Employee Travel'!F14 -> 12200 | G42: ='Employee Travel'!G14 -> 12200 | H42: ='Employee Travel'!H14 -> 12200 | I42: ='Employee Travel'!I14 -> 12200 | J42: ='Employee Travel'!J14 -> 12200 | K42: ='Employee Travel'!K14 -> 12200 | ... O42: ='Employee Travel'!O14 -> 12200 | Q42: =SUM(D42:F42) -> 36850 | R42: =SUM(G42:I42) -> 36600 | S42: =SUM(J42:L42) -> 36600 | T42: =SUM(M42:O42) -> 36600 | V42: =SUM(Q42:T42) -> 146650 | W42: =V42 -> 146650
C43: Other Operating Expenses | D43: ='Other Operating Expenses'!E22 -> 2212 | E43: ='Other Operating Expenses'!F22 -> 3210 | F43: ='Other Operating Expenses'!G22 -> 2812 | G43: ='Other Operating Expenses'!H22 -> 3212 | H43: ='Other Operating Expenses'!I22 -> 2712 | I43: ='Other Operating Expenses'!J22 -> 2712 | J43: ='Other Operating Expenses'!K22 -> 3309 | K43: ='Other Operating Expenses'!L22 -> 2712 | ... O43: ='Other Operating Expenses'!P22 -> 2712 | Q43: =SUM(D43:F43) -> 8234 | R43: =SUM(G43:I43) -> 8636 | S43: =SUM(J43:L43) -> 8733 | T43: =SUM(M43:O43) -> 8136 | V43: =SUM(Q43:T43) -> 33739 | W43: =V43 -> 33739
C44: Total Operating Expenses | D44: =SUM(D36:D43) -> 235767.84 | E44: =SUM(E36:E43) -> 243551.39 | F44: =SUM(F36:F43) -> 237952.7 | G44: =SUM(G36:G43) -> 240468.93 | H44: =SUM(H36:H43) -> 232707.17 | I44: =SUM(I36:I43) -> 227467.45 | J44: =SUM(J36:J43) -> 215509.96 | K44: =SUM(K36:K43) -> 195066.78 | ... O44: =SUM(O36:O43) -> 40001.667 | Q44: =SUM(Q36:Q43) -> 717271.94 | R44: =SUM(R36:R43) -> 700643.55 | S44: =SUM(S36:S43) -> 584814.16 | T44: =SUM(T36:T43) -> 259207.11 | V44: =SUM(V36:V43) -> 2261936.8 | W44: =SUM(W36:W43) -> 1991798.8
C45: % of Total Revenue | D45: =IFERROR(D44/D$12,"nm") -> nm | E45: =IFERROR(E44/E$12,"nm") -> 318.36783 | F45: =IFERROR(F44/F$12,"nm") -> 311.04928 | G45: =IFERROR(G44/G$12,"nm") -> 22.771679 | H45: =IFERROR(H44/H$12,"nm") -> 11.432433 | I45: =IFERROR(I44/I$12,"nm") -> 7.7409375 | J45: =IFERROR(J44/J$12,"nm") -> 3.7650238 | K45: =IFERROR(K44/K$12,"nm") -> 1.9638254 | ... O45: =IFERROR(O44/O$12,"nm") -> 0.094182512 | Q45: =IFERROR(Q44/Q$12,"nm") -> 468.80519 | R45: =IFERROR(R44/R$12,"nm") -> 11.619296 | S45: =IFERROR(S44/S$12,"nm") -> 1.9095661 | T45: =IFERROR(T44/T$12,"nm") -> 0.26379584 | V45: =IFERROR(V44/V$12,"nm") -> 1.6746528 | W45: =IFERROR(W44/W$12,"nm") -> 0.21828984
C47: Other Income | D47: -226.25 | E47: -226.25 | F47: -226.25 | G47: -226.25 | H47: -226.25 | I47: -226.25 | J47: -226.25 | K47: -226.25 | L47: -226.25 | M47: -226.25 | N47: -226.25 | O47: -226.25 | Q47: =SUM(D47:F47) -> -678.75 | R47: =SUM(G47:I47) -> -678.75 | S47: =SUM(J47:L47) -> -678.75 | T47: =SUM(M47:O47) -> -678.75 | V47: =SUM(Q47:T47) -> -2715 | W47: =O47*12 -> -2715
...

Sheet CF
C2: 2026 Forecast
C3: Cash Flow Statement
C5: ($ in actual) | D5: 46023 | E5: =EOMONTH(D5,0)+1 -> 46054 | F5: =EOMONTH(E5,0)+1 -> 46082 | G5: =EOMONTH(F5,0)+1 -> 46113 | H5: =EOMONTH(G5,0)+1 -> 46143 | I5: =EOMONTH(H5,0)+1 -> 46174 | J5: =EOMONTH(I5,0)+1 -> 46204 | K5: =EOMONTH(J5,0)+1 -> 46235 | L5: =EOMONTH(K5,0)+1 -> 46266 | ... O5: =EOMONTH(N5,0)+1 -> 46357 | Q5: Q1 '26 | R5: Q2 '26 | S5: Q3 '26 | T5: Q4 '26 | V5: 2026E
C7: Operating Activities
C8: Net Income | D8: ='P&L'!D49 -> -236344.09 | E8: ='P&L'!E49 -> -243843.02 | F8: ='P&L'!F49 -> -238262.7 | G8: ='P&L'!G49 -> -263382.35 | H8: ='P&L'!H49 -> -278277.07 | I8: ='P&L'!I49 -> -296023.69 | J8: ='P&L'!J49 -> -352653.76 | K8: ='P&L'!K49 -> -449577.46 | ... O8: ='P&L'!O49 -> -1208927.9 | Q8: =SUM(D8:F8) -> -718449.81 | R8: =SUM(G8:I8) -> -837683.11 | S8: =SUM(J8:L8) -> -1370512 | T8: =SUM(M8:O8) -> -2941548.4 | V8: =SUM(Q8:T8) -> -5868193.3
C9: Depreciation & Amortization | D9: =-'P&L'!D47 -> 226.25 | E9: =-'P&L'!E47 -> 226.25 | F9: =-'P&L'!F47 -> 226.25 | G9: =-'P&L'!G47 -> 226.25 | H9: =-'P&L'!H47 -> 226.25 | I9: =-'P&L'!I47 -> 226.25 | J9: =-'P&L'!J47 -> 226.25 | K9: =-'P&L'!K47 -> 226.25 | ... O9: =-'P&L'!O47 -> 226.25 | Q9: =SUM(D9:F9) -> 678.75 | R9: =SUM(G9:I9) -> 678.75 | S9: =SUM(J9:L9) -> 678.75 | T9: =SUM(M9:O9) -> 678.75 | V9: =SUM(Q9:T9) -> 2715
C10: Accounts Receivable | D10: 0 | E10: 15200 | F10: ='Sales Forecast'!F59-'Sales Forecast'!F49 -> 0 | G10: ='Sales Forecast'!G59-'Sales Forecast'!G49 -> -9795 | H10: ='Sales Forecast'!H59-'Sales Forecast'!H49 -> -9795 | I10: ='Sales Forecast'!I59-'Sales Forecast'!I49 -> -9030 | J10: ='Sales Forecast'!J59-'Sales Forecast'!J49 -> -27855 | K10: ='Sales Forecast'!K59-'Sales Forecast'!K49 -> -42090 | L10: ='Sales Forecast'!L59-'Sales Forecast'!L49 -> -50355 | M10: ='Sales Forecast'!M59-'Sales Forecast'!M49 -> -83415 | ... O10: ='Sales Forecast'!O59-'Sales Forecast'!O49 -> -99945 | Q10: =SUM(D10:F10) -> 15200 | R10: =SUM(G10:I10) -> -28620 | S10: =SUM(J10:L10) -> -120300 | T10: =SUM(M10:O10) -> -275040 | V10: =SUM(Q10:T10) -> -408760
C11: Accounts Payable | D11: 0 | E11: 0 | F11: 0 | G11: 0 | H11: 0 | I11: 0 | J11: 0 | K11: 0 | L11: 0 | M11: 0 | N11: 0 | O11: 0 | Q11: =SUM(D11:F11) -> 0 | R11: =SUM(G11:I11) -> 0 | S11: =SUM(J11:L11) -> 0 | T11: =SUM(M11:O11) -> 0 | V11: =SUM(Q11:T11) -> 0
C12: Credit Card | D12: 0 | E12: 0 | F12: 0 | G12: 0 | H12: 0 | I12: 0 | J12: 0 | K12: 0 | L12: 0 | M12: 0 | N12: 0 | O12: 0 | Q12: =SUM(D12:F12) -> 0 | R12: =SUM(G12:I12) -> 0 | S12: =SUM(J12:L12) -> 0 | T12: =SUM(M12:O12) -> 0 | V12: =SUM(Q12:T12) -> 0
C13: Prepaid Expenses | D13: 0 | E13: 0 | F13: 0 | G13: 0 | H13: 0 | I13: 0 | J13: 0 | K13: 0 | L13: 0 | M13: 0 | N13: 0 | O13: 0 | Q13: =SUM(D13:F13) -> 0 | R13: =SUM(G13:I13) -> 0 | S13: =SUM(J13:L13) -> 0 | T13: =SUM(M13:O13) -> 0 | V13: =SUM(Q13:T13) -> 0
C14: Accrued Payroll | D14: ='Sales Forecast'!D63-'Sales Forecast'!D64+'Salaries, Wages, & Benefits'!F27 -> 0 | E14: ='Sales Forecast'!E63-'Sales Forecast'!E64+'Salaries, Wages, & Benefits'!G27 -> 153 | F14: ='Sales Forecast'!F63-'Sales Forecast'!F64+'Salaries, Wages, & Benefits'!H27 -> 0 | G14: ='Sales Forecast'!G63-'Sales Forecast'!G64+'Salaries, Wages, & Benefits'!I27 -> 1959 | H14: ='Sales Forecast'!H63-'Sales Forecast'!H64+'Salaries, Wages, & Benefits'!J27 -> 1959 | I14: ='Sales Forecast'!I63-'Sales Forecast'!I64+'Salaries, Wages, & Benefits'!K27 -> 1806 | J14: ='Sales Forecast'!J63-'Sales Forecast'!J64+'Salaries, Wages, & Benefits'!L27 -> 5571 | K14: ='Sales Forecast'!K63-'Sales Forecast'!K64+'Salaries, Wages, & Benefits'!M27 -> 8418 | ... N14: ='Sales Forecast'!N63-'Sales Forecast'!N64+'Salaries, Wages, & Benefits'!P27 -> 18336 | O14: ='Sales Forecast'!O63-'Sales Forecast'!O64-SUM('Salaries, Wages, & Benefits'!F27:Q27) -> 19989 | Q14: =SUM(D14:F14) -> 153 | R14: =SUM(G14:I14) -> 5724 | S14: =SUM(J14:L14) -> 24060 | T14: =SUM(M14:O14) -> 55008 | V14: =SUM(Q14:T14) -> 84945
C15: Other | D15: 0 | E15: 0 | F15: 0 | G15: 0 | H15: 0 | I15: 0 | J15: 0 | K15: 0 | L15: 0 | M15: 0 | N15: 0 | O15: 0 | Q15: =SUM(D15:F15) -> 0 | R15: =SUM(G15:I15) -> 0 | S15: =SUM(J15:L15) -> 0 | T15: =SUM(M15:O15) -> 0 | V15: =SUM(Q15:T15) -> 0
C16: Cash from Operations | D16: =SUM(D8:D15) -> -236117.84 | E16: =SUM(E8:E15) -> -228263.77 | F16: =SUM(F8:F15) -> -238036.45 | G16: =SUM(G8:G15) -> -270992.1 | H16: =SUM(H8:H15) -> -285886.82 | I16: =SUM(I8:I15) -> -303021.44 | J16: =SUM(J8:J15) -> -374711.51 | K16: =SUM(K8:K15) -> -483023.21 | ... O16: =SUM(O8:O15) -> -1288657.6 | Q16: =SUM(Q8:Q15) -> -702418.06 | R16: =SUM(R8:R15) -> -859900.36 | S16: =SUM(S8:S15) -> -1466073.3 | T16: =SUM(T8:T15) -> -3160901.6 | V16: =SUM(V8:V15) -> -6189293.3
C18: Investing Activities
C19: Office Equipment | D19: -1000 | E19: -1000 | F19: -1000 | G19: -1000 | H19: -1000 | I19: -1000 | J19: -1000 | K19: -1000 | L19: -1000 | M19: -1000 | N19: -1000 | O19: -1000 | Q19: =SUM(D19:F19) -> -3000 | R19: =SUM(G19:I19) -> -3000 | S19: =SUM(J19:L19) -> -3000 | T19: =SUM(M19:O19) -> -3000 | V19: =SUM(Q19:T19) -> -12000
C20: Other | D20: 0 | E20: 0 | F20: 0 | G20: 0 | H20: 0 | I20: 0 | J20: 0 | K20: 0 | L20: 0 | M20: 0 | N20: 0 | O20: 0 | Q20: =SUM(D20:F20) -> 0 | R20: =SUM(G20:I20) -> 0 | S20: =SUM(J20:L20) -> 0 | T20: =SUM(M20:O20) -> 0 | V20: =SUM(Q20:T20) -> 0
C21: Cash from Investing | D21: =SUM(D19:D20) -> -1000 | E21: =SUM(E19:E20) -> -1000 | F21: =SUM(F19:F20) -> -1000 | G21: =SUM(G19:G20) -> -1000 | H21: =SUM(H19:H20) -> -1000 | I21: =SUM(I19:I20) -> -1000 | J21: =SUM(J19:J20) -> -1000 | K21: =SUM(K19:K20) -> -1000 | ... O21: =SUM(O19:O20) -> -1000 | Q21: =SUM(Q19:Q20) -> -3000 | R21: =SUM(R19:R20) -> -3000 | S21: =SUM(S19:S20) -> -3000 | T21: =SUM(T19:T20) -> -3000 | V21: =SUM(V19:V20) -> -12000
C23: Financing Activities
C24: Loans from Officers | D24: 0 | E24: 0 | F24: 0 | G24: 0 | H24: 0 | I24: 0 | J24: 0 | K24: 0 | L24: 0 | M24: 0 | N24: 0 | O24: 0 | Q24: =SUM(D24:F24) -> 0 | R24: =SUM(G24:I24) -> 0 | S24: =SUM(J24:L24) -> 0 | T24: =SUM(M24:O24) -> 0 | V24: =SUM(Q24:T24) -> 0
C25: SAFE | D25: 0 | E25: 0 | F25: 0 | G25: 1000000 | H25: 1000000 | I25: 0 | J25: 0 | K25: 0 | L25: 0 | M25: 0 | N25: 0 | O25: 0 | Q25: =SUM(D25:F25) -> 0 | R25: =SUM(G25:I25) -> 2000000 | S25: =SUM(J25:L25) -> 0 | T25: =SUM(M25:O25) -> 0 | V25: =SUM(Q25:T25) -> 2000000
C26: Other | D26: 0 | E26: 0 | F26: 0 | G26: 0 | H26: 0 | I26: 0 | J26: 0 | K26: 0 | L26: 0 | M26: 0 | N26: 0 | O26: 0 | Q26: =SUM(D26:F26) -> 0 | R26: =SUM(G26:I26) -> 0 | S26: =SUM(J26:L26) -> 0 | T26: =SUM(M26:O26) -> 0 | V26: =SUM(Q26:T26) -> 0
C27: Cash from Financing | D27: =SUM(D24:D26) -> 0 | E27: =SUM(E24:E26) -> 0 | F27: =SUM(F24:F26) -> 0 | G27: =SUM(G24:G26) -> 1000000 | H27: =SUM(H24:H26) -> 1000000 | I27: =SUM(I24:I26) -> 0 | J27: =SUM(J24:J26) -> 0 | K27: =SUM(K24:K26) -> 0 | ... O27: =SUM(O24:O26) -> 0 | Q27: =SUM(Q24:Q26) -> 0 | R27: =SUM(R24:R26) -> 2000000 | S27: =SUM(S24:S26) -> 0 | T27: =SUM(T24:T26) -> 0 | V27: =SUM(V24:V26) -> 2000000
C29: Net Increase in Cash | D29: =D16+D21+D27 -> -237117.84 | E29: =E16+E21+E27 -> -229263.77 | F29: =F16+F21+F27 -> -239036.45 | G29: =G16+G21+G27 -> 728007.9 | H29: =H16+H21+H27 -> 713113.18 | I29: =I16+I21+I27 -> -304021.44 | J29: =J16+J21+J27 -> -375711.51 | K29: =K16+K21+K27 -> -484023.21 | ... O29: =O16+O21+O27 -> -1289657.6 | Q29: =SUM(D29:F29) -> -705418.06 | R29: =SUM(G29:I29) -> 1137099.6 | S29: =SUM(J29:L29) -> -1469073.3 | T29: =SUM(M29:O29) -> -3163901.6 | V29: =SUM(Q29:T29) -> -4201293.3
C30: Beginning Cash Balance | D30: 2200000 | E30: =D31 -> 1962882.2 | F30: =E31 -> 1733618.4 | G30: =F31 -> 1494581.9 | H30: =G31 -> 2222589.8 | I30: =H31 -> 2935703 | J30: =I31 -> 2631681.6 | K30: =J31 -> 2255970.1 | L30: =K31 -> 1771946.9 | ... O30: =N31 -> -711635.68 | Q30: =D30 -> 2200000 | R30: =G30 -> 1494581.9 | S30: =J30 -> 2631681.6 | T30: =M30 -> 1162608.3 | V30: =D30 -> 2200000
C31: Ending Cash Balance | D31: =SUM(D29:D30) -> 1962882.2 | E31: =SUM(E29:E30) -> 1733618.4 | F31: =SUM(F29:F30) -> 1494581.9 | G31: =SUM(G29:G30) -> 2222589.8 | H31: =SUM(H29:H30) -> 2935703 | I31: =SUM(I29:I30) -> 2631681.6 | J31: =SUM(J29:J30) -> 2255970.1 | K31: =SUM(K29:K30) -> 1771946.9 | ... O31: =SUM(O29:O30) -> -2001293.3 | Q31: =SUM(Q29:Q30) -> 1494581.9 | R31: =SUM(R29:R30) -> 2631681.6 | S31: =SUM(S29:S30) -> 1162608.3 | T31: =SUM(T29:T30) -> -2001293.3 | V31: =SUM(V29:V30) -> -2001293.3
C32: Remaining Cash Burn (Months) | D32: =ROUNDDOWN(D31/-D16,0) -> 8 | E32: =ROUNDDOWN(E31/-E16,0) -> 7 | F32: =ROUNDDOWN(F31/-F16,0) -> 6 | G32: =ROUNDDOWN(G31/-G16,0) -> 8 | H32: =ROUNDDOWN(H31/-H16,0) -> 10 | I32: =ROUNDDOWN(I31/-I16,0) -> 8 | J32: =ROUNDDOWN(J31/-J16,0) -> 6 | K32: =ROUNDDOWN(K31/-K16,0) -> 3 | ... O32: =ROUNDDOWN(O31/-O16,0) -> -1

Sheet Revenue >>>

Sheet Product & Pricing List
G1: Scenario: | H1: Base | I1: =IF(H1="Low",1,IF(H1="Base",2,3)) -> 2
H3: Pricing | K3: Annualized | P3: Active
C4: Product | D4: Customer | E4: Type | F4: Frequency | G4: Metric | H4: Low | I4: Base | J4: High | K4: Low | L4: Base | M4: High | P4: Scenario
C5: AI Monitoring | D5: Federal | E5: Recurring | F5: Monthly | G5: Per AI Model | H5: 1500 | I5: 1500 | J5: 1500 | K5: =H5*12 -> 18000 | L5: =I5*12 -> 18000 | M5: =J5*12 -> 18000 | P5: =CHOOSE($I$1,H5,I5,J5) -> 1500
C6: AI Monitoring | D6: Commercial | E6: Recurring | F6: Monthly | G6: Per AI Model | H6: 1500 | I6: 1500 | J6: 1500 | K6: =H6*12 -> 18000 | L6: =I6*12 -> 18000 | M6: =J6*12 -> 18000 | P6: =CHOOSE($I$1,H6,I6,J6) -> 1500
C7: Integration Fee | D7: Both | E7: Non-Recurring | F7: Upfront | G7: Per AI Model | H7: 0 | I7: 0 | J7: 0 | P7: =CHOOSE($I$1,H7,I7,J7) -> 0
C8: Professional Services | D8: Both | E8: Non-Recurring | F8: Upfront | G8: Per Hour | H8: 255 | I8: 255 | J8: 255 | P8: =CHOOSE($I$1,H8,I8,J8) -> 255
C10: FedRAMP Path | D10: High
C11: AFFIRM Base Subscription - High | D11: 100000

Sheet Solution Offering
D1: Scenario: | E1: High | F1: =IF(E1="Low",1,IF(E1="Base",2,3)) -> 3
E3: # of Units | J3: Active
C4: Product | D4: Unit | E4: Low | F4: Base | G4: High | J4: Scenario
C5: AI Monitoring | D5: Subscription | E5: 5 | F5: 5 | G5: 5 | J5: =CHOOSE($F$1,E5,F5,G5) -> 5
C6: Integration Fee | D6: AI Model | E6: 0 | F6: 0 | G6: 0 | J6: =CHOOSE($F$1,E6,F6,G6) -> 0
C7: Professional Services - Implementation | D7: Hours | E7: 3 | F7: 3 | G7: 3 | J7: =CHOOSE($F$1,E7,F7,G7) -> 3
C8: Professional Services - Monthly | D8: Hours | E8: 2.5 | F8: 3 | G8: 3 | J8: =CHOOSE($F$1,E8,F8,G8) -> 3
E10: Month
C11: Professional Services Split | E11: 1 | F11: 2 | G11: 3+
C12: =C7 -> Professional Services - Implementation | E12: 1 | F12: 0 | G12: 0
C13: =C8 -> Professional Services - Monthly | E13: 0 | F13: 0 | G13: 1
C15: Annualized Solution Offering - Federal
C16: =C5 -> AI Monitoring | E16: =E5*'Product & Pricing List'!H5*12 -> 90000 | F16: =F5*'Product & Pricing List'!I5*12 -> 90000 | G16: =G5*'Product & Pricing List'!J5*12 -> 90000 | J16: =CHOOSE($F$1,E16,F16,G16) -> 90000
C17: =C6 -> Integration Fee | E17: =E6*'Product & Pricing List'!H7 -> 0 | F17: =F6*'Product & Pricing List'!I7 -> 0 | G17: =G6*'Product & Pricing List'!J7 -> 0 | J17: =CHOOSE($F$1,E17,F17,G17) -> 0
C18: =C7 -> Professional Services - Implementation | E18: =E7*'Product & Pricing List'!H8 -> 765 | F18: =F7*'Product & Pricing List'!I8 -> 765 | G18: =G7*'Product & Pricing List'!J8 -> 765 | J18: =CHOOSE($F$1,E18,F18,G18) -> 765
C19: =C8 -> Professional Services - Monthly | E19: =E8*'Product & Pricing List'!H8*12 -> 7650 | F19: =F8*'Product & Pricing List'!I8*12 -> 9180 | G19: =G8*'Product & Pricing List'!J8*12 -> 9180 | J19: =CHOOSE($F$1,E19,F19,G19) -> 9180
C20: Total Annualized Solution Offering - Federal | E20: =SUM(E16:E19) -> 98415 | F20: =SUM(F16:F19) -> 99945 | G20: =SUM(G16:G19) -> 99945 | J20: =SUM(J16:J19) -> 99945
C21: % Software | E21: =SUM(E16:E16)/E20 -> 0.91449474 | F21: =SUM(F16:F16)/F20 -> 0.90049527 | G21: =SUM(G16:G16)/G20 -> 0.90049527 | J21: =SUM(J16:J16)/J20 -> 0.90049527
C22: % Services | E22: =SUM(E17:E19)/E20 -> 0.085505258 | F22: =SUM(F17:F19)/F20 -> 0.099504728 | G22: =SUM(G17:G19)/G20 -> 0.099504728 | J22: =SUM(J17:J19)/J20 -> 0.099504728
C24: Annualized Solution Offering - Commercial
C25: =C16 -> AI Monitoring | E25: =E5*'Product & Pricing List'!H6*12 -> 90000 | F25: =F5*'Product & Pricing List'!I6*12 -> 90000 | G25: =G5*'Product & Pricing List'!J6*12 -> 90000 | J25: =CHOOSE($F$1,E25,F25,G25) -> 90000
C26: =C17 -> Integration Fee | E26: =E6*'Product & Pricing List'!H7 -> 0 | F26: =F6*'Product & Pricing List'!I7 -> 0 | G26: =G6*'Product & Pricing List'!J7 -> 0 | J26: =CHOOSE($F$1,E26,F26,G26) -> 0
C27: =C18 -> Professional Services - Implementation | E27: =E7*'Product & Pricing List'!H8 -> 765 | F27: =F7*'Product & Pricing List'!I8 -> 765 | G27: =G7*'Product & Pricing List'!J8 -> 765 | J27: =CHOOSE($F$1,E27,F27,G27) -> 765
C28: =C19 -> Professional Services - Monthly | E28: =E8*'Product & Pricing List'!H8*12 -> 7650 | F28: =F8*'Product & Pricing List'!I8*12 -> 9180 | G28: =G8*'Product & Pricing List'!J8*12 -> 9180 | J28: =CHOOSE($F$1,E28,F28,G28) -> 9180
C29: Total Annualized Solution Offering - Commercial | E29: =SUM(E25:E28) -> 98415 | F29: =SUM(F25:F28) -> 99945 | G29: =SUM(G25:G28) -> 99945 | J29: =SUM(J25:J28) -> 99945
C30: % Software | E30: =SUM(E25:E25)/E29 -> 0.91449474 | F30: =SUM(F25:F25)/F29 -> 0.90049527 | G30: =SUM(G25:G25)/G29 -> 0.90049527 | J30: =SUM(J25:J25)/J29 -> 0.90049527
C31: % Services | E31: =SUM(E26:E28)/E29 -> 0.085505258 | F31: =SUM(F26:F28)/F29 -> 0.099504728 | G31: =SUM(G26:G28)/G29 -> 0.099504728 | J31: =SUM(J26:J28)/J29 -> 0.099504728

Sheet Sales Forecast
C2: 2026 Forecast
C3: Sales Forecast
D5: 46023 | E5: =EOMONTH(D5,0)+1 -> 46054 | F5: =EOMONTH(E5,0)+1 -> 46082 | G5: =EOMONTH(F5,0)+1 -> 46113 | H5: =EOMONTH(G5,0)+1 -> 46143 | I5: =EOMONTH(H5,0)+1 -> 46174 | J5: =EOMONTH(I5,0)+1 -> 46204 | K5: =EOMONTH(J5,0)+1 -> 46235 | L5: =EOMONTH(K5,0)+1 -> 46266 | ... O5: =EOMONTH(N5,0)+1 -> 46357 | Q5: Q1 '26 | R5: Q2 '26 | S5: Q3 '26 | T5: Q4 '26 | V5: 2026E
C7: Govt / International Customers | D7: 0 | E7: 0 | F7: 0 | G7: 0 | H7: 0 | I7: 1 | J7: 0 | K7: 1 | L7: 0 | M7: 1 | N7: 0 | O7: 1 | Q7: =SUM(D7:F7) -> 0 | R7: =SUM(G7:I7) -> 1 | S7: =SUM(J7:L7) -> 1 | T7: =SUM(M7:O7) -> 2 | V7: =SUM(Q7:T7) -> 4
C8: Commercial Customers | D8: 1 | E8: 1 | F8: 1 | G8: 3 | H8: 5 | I8: 5 | J8: 10 | K8: 10 | L8: 12 | M8: 12 | N8: 14 | O8: 14 | Q8: =SUM(D8:F8) -> 3 | R8: =SUM(G8:I8) -> 13 | S8: =SUM(J8:L8) -> 32 | T8: =SUM(M8:O8) -> 40 | V8: =SUM(Q8:T8) -> 88
C9: Cumulative - Federal | D9: =SUM($D$7:D7) -> 0 | E9: =SUM($D$7:E7) -> 0 | F9: =SUM($D$7:F7) -> 0 | G9: =SUM($D$7:G7) -> 0 | H9: =SUM($D$7:H7) -> 0 | I9: =SUM($D$7:I7) -> 1 | J9: =SUM($D$7:J7) -> 1 | K9: =SUM($D$7:K7) -> 2 | ... O9: =SUM($D$7:O7) -> 4 | Q9: =F9 -> 0 | R9: =I9 -> 1 | S9: =L9 -> 2 | T9: =O9 -> 4 | V9: =T9 -> 4
C10: Cumulative - Commercial | D10: =SUM($D$8:D8) -> 1 | E10: =SUM($D$8:E8) -> 2 | F10: =SUM($D$8:F8) -> 3 | G10: =SUM($D$8:G8) -> 6 | H10: =SUM($D$8:H8) -> 11 | I10: =SUM($D$8:I8) -> 16 | J10: =SUM($D$8:J8) -> 26 | K10: =SUM($D$8:K8) -> 36 | ... O10: =SUM($D$8:O8) -> 88 | Q10: =F10 -> 3 | R10: =I10 -> 16 | S10: =L10 -> 48 | T10: =O10 -> 88 | V10: =T10 -> 88
C11: Cumulative - Total | D11: =SUM(D9:D10) -> 1 | E11: =SUM(E9:E10) -> 2 | F11: =SUM(F9:F10) -> 3 | G11: =SUM(G9:G10) -> 6 | H11: =SUM(H9:H10) -> 11 | I11: =SUM(I9:I10) -> 17 | J11: =SUM(J9:J10) -> 27 | K11: =SUM(K9:K10) -> 38 | ... O11: =SUM(O9:O10) -> 92 | Q11: =F11 -> 3 | R11: =I11 -> 17 | S11: =L11 -> 50 | T11: =O11 -> 92 | V11: =T11 -> 92
C13: Customers by Phase
C14: Govt Customers
C15: Month 1 | D15: =SUM($D$7:D7) -> 0 | E15: =SUM($D$7:E7) -> 0 | F15: =SUM($D$7:F7) -> 0 | G15: =SUM($D$7:G7) -> 0 | H15: =SUM($D$7:H7) -> 0 | I15: =SUM($D$7:I7) -> 1 | J15: =SUM($D$7:J7) -> 1 | K15: =SUM($D$7:K7) -> 2 | ... O15: =SUM($D$7:O7) -> 4 | Q15: =F15 -> 0 | R15: =I15 -> 1 | S15: =L15 -> 2 | T15: =O15 -> 4 | V15: =T15 -> 4
C16: Month 2 | D16: 0 | E16: 0 | F16: =SUM($D$7:D7) -> 0 | G16: =SUM($D$7:E7) -> 0 | H16: =SUM($D$7:F7) -> 0 | I16: =SUM($D$7:G7) -> 0 | J16: =SUM($D$7:H7) -> 0 | K16: =SUM($D$7:I7) -> 1 | L16: =SUM($D$7:J7) -> 1 | M16: =SUM($D$7:K7) -> 2 | ... O16: =SUM($D$7:M7) -> 3 | Q16: =F16 -> 0 | R16: =I16 -> 0 | S16: =L16 -> 1 | T16: =O16 -> 3 | V16: =T16 -> 3
C17: Month 3+ | D17: 0 | E17: 0 | F17: 0 | G17: =SUM($D$7:D7) -> 0 | H17: =SUM($D$7:E7) -> 0 | I17: =SUM($D$7:F7) -> 0 | J17: =SUM($D$7:G7) -> 0 | K17: =SUM($D$7:H7) -> 0 | L17: =SUM($D$7:I7) -> 1 | M17: =SUM($D$7:J7) -> 1 | N17: =SUM($D$7:K7) -> 2 | O17: =SUM($D$7:L7) -> 2 | Q17: =F17 -> 0 | R17: =I17 -> 0 | S17: =L17 -> 1 | T17: =O17 -> 2 | V17: =T17 -> 2
C18: Commercial
C19: Month 1 | D19: =SUM($D$8:D8) -> 1 | E19: =SUM($D$8:E8) -> 2 | F19: =SUM($D$8:F8) -> 3 | G19: =SUM($D$8:G8) -> 6 | H19: =SUM($D$8:H8) -> 11 | I19: =SUM($D$8:I8) -> 16 | J19: =SUM($D$8:J8) -> 26 | K19: =SUM($D$8:K8) -> 36 | ... O19: =SUM($D$8:O8) -> 88 | Q19: =F19 -> 3 | R19: =I19 -> 16 | S19: =L19 -> 48 | T19: =O19 -> 88 | V19: =T19 -> 88
C20: Month 2 | D20: 0 | E20: 0 | F20: =SUM($D$8:D8) -> 1 | G20: =SUM($D$8:E8) -> 2 | H20: =SUM($D$8:F8) -> 3 | I20: =SUM($D$8:G8) -> 6 | J20: =SUM($D$8:H8) -> 11 | K20: =SUM($D$8:I8) -> 16 | L20: =SUM($D$8:J8) -> 26 | M20: =SUM($D$8:K8) -> 36 | ... O20: =SUM($D$8:M8) -> 60 | Q20: =F20 -> 1 | R20: =I20 -> 6 | S20: =L20 -> 26 | T20: =O20 -> 60 | V20: =T20 -> 60
C21: Month 3+ | D21: 0 | E21: 0 | F21: 0 | G21: =SUM($D$8:D8) -> 1 | H21: =SUM($D$8:E8) -> 2 | I21: =SUM($D$8:F8) -> 3 | J21: =SUM($D$8:G8) -> 6 | K21: =SUM($D$8:H8) -> 11 | L21: =SUM($D$8:I8) -> 16 | M21: =SUM($D$8:J8) -> 26 | N21: =SUM($D$8:K8) -> 36 | O21: =SUM($D$8:L8) -> 48 | Q21: =F21 -> 0 | R21: =I21 -> 3 | S21: =L21 -> 16 | T21: =O21 -> 48 | V21: =T21 -> 48
C23: Products
C24: Federal
C25: AI Monitoring | D25: =D17*'Solution Offering'!$J5 -> 0 | E25: =E17*'Solution Offering'!$J5 -> 0 | F25: =F17*'Solution Offering'!$J5 -> 0 | G25: =G17*'Solution Offering'!$J5 -> 0 | H25: =H17*'Solution Offering'!$J5 -> 0 | I25: =I17*'Solution Offering'!$J5 -> 0 | J25: =J17*'Solution Offering'!$J5 -> 0 | K25: =K17*'Solution Offering'!$J5 -> 0 | ... O25: =O17*'Solution Offering'!$J5 -> 10 | Q25: =F25 -> 0 | R25: =I25 -> 0 | S25: =L25 -> 5 | T25: =O25 -> 10 | V25: =T25 -> 10
C26: Integration Fee | D26: 0 | E26: =(E25-D25)*'Solution Offering'!$J6 -> 0 | F26: =(F25-E25)*'Solution Offering'!$J6 -> 0 | G26: =(G25-F25)*'Solution Offering'!$J6 -> 0 | H26: =(H25-G25)*'Solution Offering'!$J6 -> 0 | I26: =(I25-H25)*'Solution Offering'!$J6 -> 0 | J26: =(J25-I25)*'Solution Offering'!$J6 -> 0 | K26: =(K25-J25)*'Solution Offering'!$J6 -> 0 | L26: =(L25-K25)*'Solution Offering'!$J6 -> 0 | ... O26: =(O25-N25)*'Solution Offering'!$J6 -> 0 | Q26: =SUM(D26:F26) -> 0 | R26: =SUM(G26:I26) -> 0 | S26: =SUM(J26:L26) -> 0 | T26: =SUM(M26:O26) -> 0 | V26: =SUM(Q26:T26) -> 0
C27: Professional Services - Implementation | D27: 0 | E27: =(E15-D15)*'Solution Offering'!$J7*'Solution Offering'!$E$12+(E16-D16)*'Solution Offering'!$J7*'Solution Offering'!$F$12+('Sales Forecast'!E17-'Sales Forecast'!D17)*'Solution Offering'!$J7*'Solution Offering'!$G$12 -> 0 | F27: =(F15-E15)*'Solution Offering'!$J7*'Solution Offering'!$E$12+(F16-E16)*'Solution Offering'!$J7*'Solution Offering'!$F$12+('Sales Forecast'!F17-'Sales Forecast'!E17)*'Solution Offering'!$J7*'Solution Offering'!$G$12 -> 0 | G27: =(G15-F15)*'Solution Offering'!$J7*'Solution Offering'!$E$12+(G16-F16)*'Solution Offering'!$J7*'Solution Offering'!$F$12+('Sales Forecast'!G17-'Sales Forecast'!F17)*'Solution Offering'!$J7*'Solution Offering'!$G$12 -> 0 | H27: =(H15-G15)*'Solution Offering'!$J7*'Solution Offering'!$E$12+(H16-G16)*'Solution Offering'!$J7*'Solution Offering'!$F$12+('Sales Forecast'!H17-'Sales Forecast'!G17)*'Solution Offering'!$J7*'Solution Offering'!$G$12 -> 0 | I27: =(I15-H15)*'Solution Offering'!$J7*'Solution Offering'!$E$12+(I16-H16)*'Solution Offering'!$J7*'Solution Offering'!$F$12+('Sales Forecast'!I17-'Sales Forecast'!H17)*'Solution Offering'!$J7*'Solution Offering'!$G$12 -> 3 | J27: =(J15-I15)*'Solution Offering'!$J7*'Solution Offering'!$E$12+(J16-I16)*'Solution Offering'!$J7*'Solution Offering'!$F$12+('Sales Forecast'!J17-'Sales Forecast'!I17)*'Solution Offering'!$J7*'Solution Offering'!$G$12 -> 0 | K27: =(K15-J15)*'Solution Offering'!$J7*'Solution Offering'!$E$12+(K16-J16)*'Solution Offering'!$J7*'Solution Offering'!$F$12+('Sales Forecast'!K17-'Sales Forecast'!J17)*'Solution Offering'!$J7*'Solution Offering'!$G$12 -> 3 | L27: =(L15-K15)*'Solution Offering'!$J7*'Solution Offering'!$E$12+(L16-K16)*'Solution Offering'!$J7*'Solution Offering'!$F$12+('Sales Forecast'!L17-'Sales Forecast'!K17)*'Solution Offering'!$J7*'Solution Offering'!$G$12 -> 0 | ... O27: =(O15-N15)*'Solution Offering'!$J7*'Solution Offering'!$E$12+(O16-N16)*'Solution Offering'!$J7*'Solution Offering'!$F$12+('Sales Forecast'!O17-'Sales Forecast'!N17)*'Solution Offering'!$J7*'Solution Offering'!$G$12 -> 3 | Q27: =SUM(D27:F27) -> 0 | R27: =SUM(G27:I27) -> 3 | S27: =SUM(J27:L27) -> 3 | T27: =SUM(M27:O27) -> 6 | V27: =SUM(Q27:T27) -> 12
C28: Professional Services - Monthly | D28: =D15*'Solution Offering'!$J8*'Solution Offering'!$E$13+'Sales Forecast'!D16*'Solution Offering'!$J8*'Solution Offering'!$F$13+'Sales Forecast'!D17*'Solution Offering'!$J8*'Solution Offering'!$G$13 -> 0 | E28: =E15*'Solution Offering'!$J8*'Solution Offering'!$E$13+'Sales Forecast'!E16*'Solution Offering'!$J8*'Solution Offering'!$F$13+'Sales Forecast'!E17*'Solution Offering'!$J8*'Solution Offering'!$G$13 -> 0 | F28: =F15*'Solution Offering'!$J8*'Solution Offering'!$E$13+'Sales Forecast'!F16*'Solution Offering'!$J8*'Solution Offering'!$F$13+'Sales Forecast'!F17*'Solution Offering'!$J8*'Solution Offering'!$G$13 -> 0 | G28: =G15*'Solution Offering'!$J8*'Solution Offering'!$E$13+'Sales Forecast'!G16*'Solution Offering'!$J8*'Solution Offering'!$F$13+'Sales Forecast'!G17*'Solution Offering'!$J8*'Solution Offering'!$G$13 -> 0 | H28: =H15*'Solution Offering'!$J8*'Solution Offering'!$E$13+'Sales Forecast'!H16*'Solution Offering'!$J8*'Solution Offering'!$F$13+'Sales Forecast'!H17*'Solution Offering'!$J8*'Solution Offering'!$G$13 -> 0 | I28: =I15*'Solution Offering'!$J8*'Solution Offering'!$E$13+'Sales Forecast'!I16*'Solution Offering'!$J8*'Solution Offering'!$F$13+'Sales Forecast'!I17*'Solution Offering'!$J8*'Solution Offering'!$G$13 -> 0 | J28: =J15*'Solution Offering'!$J8*'Solution Offering'!$E$13+'Sales Forecast'!J16*'Solution Offering'!$J8*'Solution Offering'!$F$13+'Sales Forecast'!J17*'Solution Offering'!$J8*'Solution Offering'!$G$13 -> 0 | K28: =K15*'Solution Offering'!$J8*'Solution Offering'!$E$13+'Sales Forecast'!K16*'Solution Offering'!$J8*'Solution Offering'!$F$13+'Sales Forecast'!K17*'Solution Offering'!$J8*'Solution Offering'!$G$13 -> 0 | ... O28: =O15*'Solution Offering'!$J8*'Solution Offering'!$E$13+'Sales Forecast'!O16*'Solution Offering'!$J8*'Solution Offering'!$F$13+'Sales Forecast'!O17*'Solution Offering'!$J8*'Solution Offering'!$G$13 -> 6 | Q28: =SUM(D28:F28) -> 0 | R28: =SUM(G28:I28) -> 0 | S28: =SUM(J28:L28) -> 3 | T28: =SUM(M28:O28) -> 15 | V28: =SUM(Q28:T28) -> 18
C29: Commercial
C30: AI Monitoring | D30: =D21*'Solution Offering'!$J5 -> 0 | E30: =E21*'Solution Offering'!$J5 -> 0 | F30: =F21*'Solution Offering'!$J5 -> 0 | G30: =G21*'Solution Offering'!$J5 -> 5 | H30: =H21*'Solution Offering'!$J5 -> 10 | I30: =I21*'Solution Offering'!$J5 -> 15 | J30: =J21*'Solution Offering'!$J5 -> 30 | K30: =K21*'Solution Offering'!$J5 -> 55 | ... O30: =O21*'Solution Offering'!$J5 -> 240 | Q30: =F30 -> 0 | R30: =I30 -> 15 | S30: =L30 -> 80 | T30: =O30 -> 240 | V30: =T30 -> 240
C31: Integration Fee | D31: 0 | E31: =(E30-D30)*'Solution Offering'!$J6 -> 0 | F31: =(F30-E30)*'Solution Offering'!$J6 -> 0 | G31: =(G30-F30)*'Solution Offering'!$J6 -> 0 | H31: =(H30-G30)*'Solution Offering'!$J6 -> 0 | I31: =(I30-H30)*'Solution Offering'!$J6 -> 0 | J31: =(J30-I30)*'Solution Offering'!$J6 -> 0 | K31: =(K30-J30)*'Solution Offering'!$J6 -> 0 | L31: =(L30-K30)*'Solution Offering'!$J6 -> 0 | ... O31: =(O30-N30)*'Solution Offering'!$J6 -> 0 | Q31: =SUM(D31:F31) -> 0 | R31: =SUM(G31:I31) -> 0 | S31: =SUM(J31:L31) -> 0 | T31: =SUM(M31:O31) -> 0 | V31: =SUM(Q31:T31) -> 0
C32: Professional Services - Implementation | D32: 0 | E32: =(E19-D19)*'Solution Offering'!$J7*'Solution Offering'!$E$12+('Sales Forecast'!E20-'Sales Forecast'!D20)*'Solution Offering'!$J7*'Solution Offering'!$F$12+('Sales Forecast'!E21-'Sales Forecast'!D21)*'Solution Offering'!$J7*'Solution Offering'!$G$12 -> 3 | F32: =(F19-E19)*'Solution Offering'!$J7*'Solution Offering'!$E$12+('Sales Forecast'!F20-'Sales Forecast'!E20)*'Solution Offering'!$J7*'Solution Offering'!$F$12+('Sales Forecast'!F21-'Sales Forecast'!E21)*'Solution Offering'!$J7*'Solution Offering'!$G$12 -> 3 | G32: =(G19-F19)*'Solution Offering'!$J7*'Solution Offering'!$E$12+('Sales Forecast'!G20-'Sales Forecast'!F20)*'Solution Offering'!$J7*'Solution Offering'!$F$12+('Sales Forecast'!G21-'Sales Forecast'!F21)*'Solution Offering'!$J7*'Solution Offering'!$G$12 -> 9 | H32: =(H19-G19)*'Solution Offering'!$J7*'Solution Offering'!$E$12+('Sales Forecast'!H20-'Sales Forecast'!G20)*'Solution Offering'!$J7*'Solution Offering'!$F$12+('Sales Forecast'!H21-'Sales Forecast'!G21)*'Solution Offering'!$J7*'Solution Offering'!$G$12 -> 15 | I32: =(I19-H19)*'Solution Offering'!$J7*'Solution Offering'!$E$12+('Sales Forecast'!I20-'Sales Forecast'!H20)*'Solution Offering'!$J7*'Solution Offering'!$F$12+('Sales Forecast'!I21-'Sales Forecast'!H21)*'Solution Offering'!$J7*'Solution Offering'!$G$12 -> 15 | J32: =(J19-I19)*'Solution Offering'!$J7*'Solution Offering'!$E$12+('Sales Forecast'!J20-'Sales Forecast'!I20)*'Solution Offering'!$J7*'Solution Offering'!$F$12+('Sales Forecast'!J21-'Sales Forecast'!I21)*'Solution Offering'!$J7*'Solution Offering'!$G$12 -> 30 | K32: =(K19-J19)*'Solution Offering'!$J7*'Solution Offering'!$E$12+('Sales Forecast'!K20-'Sales Forecast'!J20)*'Solution Offering'!$J7*'Solution Offering'!$F$12+('Sales Forecast'!K21-'Sales Forecast'!J21)*'Solution Offering'!$J7*'Solution Offering'!$G$12 -> 30 | L32: =(L19-K19)*'Solution Offering'!$J7*'Solution Offering'!$E$12+('Sales Forecast'!L20-'Sales Forecast'!K20)*'Solution Offering'!$J7*'Solution Offering'!$F$12+('Sales Forecast'!L21-'Sales Forecast'!K21)*'Solution Offering'!$J7*'Solution Offering'!$G$12 -> 36 | ... O32: =(O19-N19)*'Solution Offering'!$J7*'Solution Offering'!$E$12+('Sales Forecast'!O20-'Sales Forecast'!N20)*'Solution Offering'!$J7*'Solution Offering'!$F$12+('Sales Forecast'!O21-'Sales Forecast'!N21)*'Solution Offering'!$J7*'Solution Offering'!$G$12 -> 42 | Q32: =SUM(D32:F32) -> 6 | R32: =SUM(G32:I32) -> 39 | S32: =SUM(J32:L32) -> 96 | T32: =SUM(M32:O32) -> 120 | V32: =SUM(Q32:T32) -> 261
C33: Professional Services - Monthly | D33: =D19*'Solution Offering'!$J8*'Solution Offering'!$E$13+'Sales Forecast'!D20*'Solution Offering'!$J8*'Solution Offering'!$F$13+'Sales Forecast'!D21*'Solution Offering'!$J8*'Solution Offering'!$G$13 -> 0 | E33: =E19*'Solution Offering'!$J8*'Solution Offering'!$E$13+'Sales Forecast'!E20*'Solution Offering'!$J8*'Solution Offering'!$F$13+'Sales Forecast'!E21*'Solution Offering'!$J8*'Solution Offering'!$G$13 -> 0 | F33: =F19*'Solution Offering'!$J8*'Solution Offering'!$E$13+'Sales Forecast'!F20*'Solution Offering'!$J8*'Solution Offering'!$F$13+'Sales Forecast'!F21*'Solution Offering'!$J8*'Solution Offering'!$G$13 -> 0 | G33: =G19*'Solution Offering'!$J8*'Solution Offering'!$E$13+'Sales Forecast'!G20*'Solution Offering'!$J8*'Solution Offering'!$F$13+'Sales Forecast'!G21*'Solution Offering'!$J8*'Solution Offering'!$G$13 -> 3 | H33: =H19*'Solution Offering'!$J8*'Solution Offering'!$E$13+'Sales Forecast'!H20*'Solution Offering'!$J8*'Solution Offering'!$F$13+'Sales Forecast'!H21*'Solution Offering'!$J8*'Solution Offering'!$G$13 -> 6 | I33: =I19*'Solution Offering'!$J8*'Solution Offering'!$E$13+'Sales Forecast'!I20*'Solution Offering'!$J8*'Solution Offering'!$F$13+'Sales Forecast'!I21*'Solution Offering'!$J8*'Solution Offering'!$G$13 -> 9 | J33: =J19*'Solution Offering'!$J8*'Solution Offering'!$E$13+'Sales Forecast'!J20*'Solution Offering'!$J8*'Solution Offering'!$F$13+'Sales Forecast'!J21*'Solution Offering'!$J8*'Solution Offering'!$G$13 -> 18 | K33: =K19*'Solution Offering'!$J8*'Solution Offering'!$E$13+'Sales Forecast'!K20*'Solution Offering'!$J8*'Solution Offering'!$F$13+'Sales Forecast'!K21*'Solution Offering'!$J8*'Solution Offering'!$G$13 -> 33 | ... O33: =O19*'Solution Offering'!$J8*'Solution Offering'!$E$13+'Sales Forecast'!O20*'Solution Offering'!$J8*'Solution Offering'!$F$13+'Sales Forecast'!O21*'Solution Offering'!$J8*'Solution Offering'!$G$13 -> 144 | Q33: =SUM(D33:F33) -> 0 | R33: =SUM(G33:I33) -> 18 | S33: =SUM(J33:L33) -> 99 | T33: =SUM(M33:O33) -> 330 | V33: =SUM(Q33:T33) -> 447
C35: Revenue
C36: Federal
C37: AI Monitoring | D37: =D25*'Product & Pricing List'!$P5 -> 0 | E37: =E25*'Product & Pricing List'!$P5 -> 0 | F37: =F25*'Product & Pricing List'!$P5 -> 0 | G37: =G25*'Product & Pricing List'!$P5 -> 0 | H37: =H25*'Product & Pricing List'!$P5 -> 0 | I37: =I25*'Product & Pricing List'!$P5 -> 0 | J37: =J25*'Product & Pricing List'!$P5 -> 0 | K37: =K25*'Product & Pricing List'!$P5 -> 0 | ... O37: =O25*'Product & Pricing List'!$P5 -> 15000 | Q37: =SUM(D37:F37) -> 0 | R37: =SUM(G37:I37) -> 0 | S37: =SUM(J37:L37) -> 7500 | T37: =SUM(M37:O37) -> 37500 | V37: =SUM(Q37:T37) -> 45000
C38: Integration Fee | D38: =D26*'Product & Pricing List'!$P7 -> 0 | E38: =E26*'Product & Pricing List'!$P7 -> 0 | F38: =F26*'Product & Pricing List'!$P7 -> 0 | G38: =G26*'Product & Pricing List'!$P7 -> 0 | H38: =H26*'Product & Pricing List'!$P7 -> 0 | I38: =I26*'Product & Pricing List'!$P7 -> 0 | J38: =J26*'Product & Pricing List'!$P7 -> 0 | K38: =K26*'Product & Pricing List'!$P7 -> 0 | ... O38: =O26*'Product & Pricing List'!$P7 -> 0 | Q38: =SUM(D38:F38) -> 0 | R38: =SUM(G38:I38) -> 0 | S38: =SUM(J38:L38) -> 0 | T38: =SUM(M38:O38) -> 0 | V38: =SUM(Q38:T38) -> 0
C39: Professional Services - Implementation | D39: =D27*'Product & Pricing List'!$P8 -> 0 | E39: =E27*'Product & Pricing List'!$P8 -> 0 | F39: =F27*'Product & Pricing List'!$P8 -> 0 | G39: =G27*'Product & Pricing List'!$P8 -> 0 | H39: =H27*'Product & Pricing List'!$P8 -> 0 | I39: =I27*'Product & Pricing List'!$P8 -> 765 | J39: =J27*'Product & Pricing List'!$P8 -> 0 | K39: =K27*'Product & Pricing List'!$P8 -> 765 | ... O39: =O27*'Product & Pricing List'!$P8 -> 765 | Q39: =SUM(D39:F39) -> 0 | R39: =SUM(G39:I39) -> 765 | S39: =SUM(J39:L39) -> 765 | T39: =SUM(M39:O39) -> 1530 | V39: =SUM(Q39:T39) -> 3060
C40: Professional Services - Monthly | D40: =D28*'Product & Pricing List'!$P8 -> 0 | E40: =E28*'Product & Pricing List'!$P8 -> 0 | F40: =F28*'Product & Pricing List'!$P8 -> 0 | G40: =G28*'Product & Pricing List'!$P8 -> 0 | H40: =H28*'Product & Pricing List'!$P8 -> 0 | I40: =I28*'Product & Pricing List'!$P8 -> 0 | J40: =J28*'Product & Pricing List'!$P8 -> 0 | K40: =K28*'Product & Pricing List'!$P8 -> 0 | ... O40: =O28*'Product & Pricing List'!$P8 -> 1530 | Q40: =SUM(D40:F40) -> 0 | R40: =SUM(G40:I40) -> 0 | S40: =SUM(J40:L40) -> 765 | T40: =SUM(M40:O40) -> 3825 | V40: =SUM(Q40:T40) -> 4590
C41: Total Revenue - Federal | D41: =SUM(D37:D40) -> 0 | E41: =SUM(E37:E40) -> 0 | F41: =SUM(F37:F40) -> 0 | G41: =SUM(G37:G40) -> 0 | H41: =SUM(H37:H40) -> 0 | I41: =SUM(I37:I40) -> 765 | J41: =SUM(J37:J40) -> 0 | K41: =SUM(K37:K40) -> 765 | ... O41: =SUM(O37:O40) -> 17295 | Q41: =SUM(Q37:Q40) -> 0 | R41: =SUM(R37:R40) -> 765 | S41: =SUM(S37:S40) -> 9030 | T41: =SUM(T37:T40) -> 42855 | V41: =SUM(V37:V40) -> 52650
C42: Commercial
C43: AI Monitoring | D43: =D30*'Product & Pricing List'!$P6 -> 0 | E43: =E30*'Product & Pricing List'!$P6 -> 0 | F43: =F30*'Product & Pricing List'!$P6 -> 0 | G43: =G30*'Product & Pricing List'!$P6 -> 7500 | H43: =H30*'Product & Pricing List'!$P6 -> 15000 | I43: =I30*'Product & Pricing List'!$P6 -> 22500 | J43: =J30*'Product & Pricing List'!$P6 -> 45000 | K43: =K30*'Product & Pricing List'!$P6 -> 82500 | ... O43: =O30*'Product & Pricing List'!$P6 -> 360000 | Q43: =SUM(D43:F43) -> 0 | R43: =SUM(G43:I43) -> 45000 | S43: =SUM(J43:L43) -> 247500 | T43: =SUM(M43:O43) -> 825000 | V43: =SUM(Q43:T43) -> 1117500
C44: Integration Fee | D44: =D31*'Product & Pricing List'!$P7 -> 0 | E44: =E31*'Product & Pricing List'!$P7 -> 0 | F44: =F31*'Product & Pricing List'!$P7 -> 0 | G44: =G31*'Product & Pricing List'!$P7 -> 0 | H44: =H31*'Product & Pricing List'!$P7 -> 0 | I44: =I31*'Product & Pricing List'!$P7 -> 0 | J44: =J31*'Product & Pricing List'!$P7 -> 0 | K44: =K31*'Product & Pricing List'!$P7 -> 0 | ... O44: =O31*'Product & Pricing List'!$P7 -> 0 | Q44: =SUM(D44:F44) -> 0 | R44: =SUM(G44:I44) -> 0 | S44: =SUM(J44:L44) -> 0 | T44: =SUM(M44:O44) -> 0 | V44: =SUM(Q44:T44) -> 0
